<?xml version="1.0" ?>
<robot name="robotleg_1_1" xmlns:xacro="http://www.ros.org/wiki/xacro">

<xacro:include filename="$(find robotleg_1_1_description)/urdf/materials.xacro" />
<xacro:include filename="$(find robotleg_1_1_description)/urdf/robotleg_1_1.trans" />
<xacro:include filename="$(find robotleg_1_1_description)/urdf/robotleg_1_1.gazebo" />
<link name="base_link">
  <inertial>
    <origin rpy="0 0 0" xyz="-9.73978003016387e-15 0.0 0.5225"/>
    <mass value="0.060303022889018544"/>
    <inertia ixx="8e-06" ixy="0.0" ixz="0.0" iyy="8e-06" iyz="-0.0" izz="1.6e-05"/>
  </inertial>
  <visual>
    <origin rpy="0 0 0" xyz="0 0 0"/>
    <geometry>
      <mesh filename="package://robotleg_1_1_description/meshes/base_link.stl" scale="0.001 0.001 0.001"/>
    </geometry>
    <material name="silver"/>
  </visual>
  <collision>
    <origin rpy="0 0 0" xyz="0 0 0"/>
    <geometry>
      <mesh filename="package://robotleg_1_1_description/meshes/base_link.stl" scale="0.001 0.001 0.001"/>
    </geometry>
  </collision>
</link>

<link name="joint_lower_1">
  <inertial>
    <origin rpy="0 0 0" xyz="-0.007000000000005211 0.005782222659981283 -0.019178043963505642"/>
    <mass value="0.051804524029768935"/>
    <inertia ixx="3.8e-05" ixy="-0.0" ixz="-0.0" iyy="2.3e-05" iyz="-3e-06" izz="3.3e-05"/>
  </inertial>
  <visual>
    <origin rpy="0 0 0" xyz="-0.007 0.01 -0.52"/>
    <geometry>
      <mesh filename="package://robotleg_1_1_description/meshes/joint_lower_1.stl" scale="0.001 0.001 0.001"/>
    </geometry>
    <material name="silver"/>
  </visual>
  <collision>
    <origin rpy="0 0 0" xyz="-0.007 0.01 -0.52"/>
    <geometry>
      <mesh filename="package://robotleg_1_1_description/meshes/joint_lower_1.stl" scale="0.001 0.001 0.001"/>
    </geometry>
  </collision>
</link>

<link name="motor_1">
  <inertial>
    <origin rpy="0 0 0" xyz="-0.007777568889405516 0.028507142059971374 -0.013223335744453169"/>
    <mass value="0.45909174206904396"/>
    <inertia ixx="0.00019" ixy="0.0" ixz="0.0" iyy="7.2e-05" iyz="2e-06" izz="0.00019"/>
  </inertial>
  <visual>
    <origin rpy="0 0 0" xyz="-0.00775 0.02 -0.503423"/>
    <geometry>
      <mesh filename="package://robotleg_1_1_description/meshes/motor_1.stl" scale="0.001 0.001 0.001"/>
    </geometry>
    <material name="silver"/>
  </visual>
  <collision>
    <origin rpy="0 0 0" xyz="-0.00775 0.02 -0.503423"/>
    <geometry>
      <mesh filename="package://robotleg_1_1_description/meshes/motor_1.stl" scale="0.001 0.001 0.001"/>
    </geometry>
  </collision>
</link>

<link name="joint_1">
  <inertial>
    <origin rpy="0 0 0" xyz="-0.019923558879193445 0.46315480536145676 -0.03481870209136767"/>
    <mass value="0.0197994934350134"/>
    <inertia ixx="1e-06" ixy="0.0" ixz="0.0" iyy="2e-06" iyz="0.0" izz="1e-06"/>
  </inertial>
  <visual>
    <origin rpy="0 0 0" xyz="-0.019925 0.497075 -0.532"/>
    <geometry>
      <mesh filename="package://robotleg_1_1_description/meshes/joint_1.stl" scale="0.001 0.001 0.001"/>
    </geometry>
    <material name="silver"/>
  </visual>
  <collision>
    <origin rpy="0 0 0" xyz="-0.019925 0.497075 -0.532"/>
    <geometry>
      <mesh filename="package://robotleg_1_1_description/meshes/joint_1.stl" scale="0.001 0.001 0.001"/>
    </geometry>
  </collision>
</link>

<link name="joint_upper_1">
  <inertial>
    <origin rpy="0 0 0" xyz="-0.004749499986316871 0.04476354878878746 -0.032938632285812564"/>
    <mass value="0.6663346958643348"/>
    <inertia ixx="0.001306" ixy="-0.0" ixz="-0.0" iyy="0.000437" iyz="-2.2e-05" izz="0.001073"/>
  </inertial>
  <visual>
    <origin rpy="0 0 0" xyz="-0.004762 0.0358 -0.505249"/>
    <geometry>
      <mesh filename="package://robotleg_1_1_description/meshes/joint_upper_1.stl" scale="0.001 0.001 0.001"/>
    </geometry>
    <material name="silver"/>
  </visual>
  <collision>
    <origin rpy="0 0 0" xyz="-0.004762 0.0358 -0.505249"/>
    <geometry>
      <mesh filename="package://robotleg_1_1_description/meshes/joint_upper_1.stl" scale="0.001 0.001 0.001"/>
    </geometry>
  </collision>
</link>

<joint name="Rigid12" type="fixed">
  <origin rpy="0 0 0" xyz="0.007 -0.01 0.52"/>
  <parent link="base_link"/>
  <child link="joint_lower_1"/>
</joint>

<joint name="Rigid13" type="fixed">
  <origin rpy="0 0 0" xyz="0.00075 -0.01 -0.016577"/>
  <parent link="joint_lower_1"/>
  <child link="motor_1"/>
</joint>

<joint name="Rev14" type="continuous">
  <origin rpy="0 0 0" xyz="0.012175 -0.477075 0.028577"/>
  <parent link="motor_1"/>
  <child link="joint_1"/>
  <axis xyz="0.0 -1.0 0.0"/>
</joint>

<joint name="Rigid15" type="fixed">
  <origin rpy="0 0 0" xyz="-0.015163 0.461275 -0.026751"/>
  <parent link="joint_1"/>
  <child link="joint_upper_1"/>
</joint>

</robot>
