<?xml version="1.0" ?>
<robot name="robotleg_1_1" xmlns:xacro="http://www.ros.org/wiki/xacro">

<xacro:include filename="$(find robotleg_1_1_description)/urdf/materials.xacro" />
<xacro:include filename="$(find robotleg_1_1_description)/urdf/robotleg_1_1.trans" />
<xacro:include filename="$(find robotleg_1_1_description)/urdf/robotleg_1_1.gazebo" />
<link name="base_link">
  <inertial>
    <origin rpy="0 0 0" xyz="-2.2158107671284978e-05 0.006454942770471819 0.49457307573443965"/>
    <mass value="0.5711992889878322"/>
    <inertia ixx="0.000304" ixy="0.0" ixz="0.0" iyy="0.000161" iyz="1.8e-05" izz="0.000249"/>
  </inertial>
  <visual>
    <origin rpy="0 0 0" xyz="0 0 0"/>
    <geometry>
      <mesh filename="package://robotleg_1_1_description/meshes/base_link.stl" scale="0.001 0.001 0.001"/>
    </geometry>
    <material name="silver_default"/>
  </visual>
  <collision>
    <origin rpy="0 0 0" xyz="0 0 0"/>
    <geometry>
      <mesh filename="package://robotleg_1_1_description/meshes/base_link.stl" scale="0.001 0.001 0.001"/>
    </geometry>
  </collision>
</link>

<link name="link1_1">
  <inertial>
    <origin rpy="0 0 0" xyz="1.2182193717565268e-05 0.04972607687249734 -0.023971945516487625"/>
    <mass value="0.6861340813991533"/>
    <inertia ixx="0.001354" ixy="-0.0" ixz="0.0" iyy="0.00045" iyz="-2e-06" izz="0.001109"/>
  </inertial>
  <visual>
    <origin rpy="0 0 0" xyz="0.0 0.042 -0.497"/>
    <geometry>
      <mesh filename="package://robotleg_1_1_description/meshes/link1_1.stl" scale="0.001 0.001 0.001"/>
    </geometry>
    <material name="silver_default"/>
  </visual>
  <collision>
    <origin rpy="0 0 0" xyz="0.0 0.042 -0.497"/>
    <geometry>
      <mesh filename="package://robotleg_1_1_description/meshes/link1_1.stl" scale="0.001 0.001 0.001"/>
    </geometry>
  </collision>
</link>

<joint name="Rev16" type="continuous">
  <origin rpy="0 0 0" xyz="0.0 -0.042 0.497"/>
  <parent link="base_link"/>
  <child link="link1_1"/>
  <axis xyz="0.0 -1.0 0.0"/>
</joint>

</robot>
