<?xml version="1.0" ?>
<!-- =================================================================================== -->
<!-- |    This document was autogenerated by xacro from /home/vegard_ubuntu/urdftest_ws/src/robotleg_description/urdf/robotleg.xacro | -->
<!-- |    EDITING THIS FILE BY HAND IS NOT RECOMMENDED                                 | -->
<!-- =================================================================================== -->
<robot name="robotleg">
    <material name="silver">
        <color rgba="0.700 0.700 0.700 1.000" />
    </material>
    <transmission name="Rev22_tran">
        <type>transmission_interface/SimpleTransmission</type>
        <joint name="Rev22">
            <hardwareInterface>hardware_interface/EffortJointInterface</hardwareInterface>
        </joint>
        <actuator name="Rev22_actr">
            <hardwareInterface>hardware_interface/EffortJointInterface</hardwareInterface>
            <mechanicalReduction>1</mechanicalReduction>
        </actuator>
    </transmission>
    <transmission name="Rev24_tran">
        <type>transmission_interface/SimpleTransmission</type>
        <joint name="Rev24">
            <hardwareInterface>hardware_interface/EffortJointInterface</hardwareInterface>
        </joint>
        <actuator name="Rev24_actr">
            <hardwareInterface>hardware_interface/EffortJointInterface</hardwareInterface>
            <mechanicalReduction>1</mechanicalReduction>
        </actuator>
    </transmission>
    <transmission name="Rev26_tran">
        <type>transmission_interface/SimpleTransmission</type>
        <joint name="Rev26">
            <hardwareInterface>hardware_interface/EffortJointInterface</hardwareInterface>
        </joint>
        <actuator name="Rev26_actr">
            <hardwareInterface>hardware_interface/EffortJointInterface</hardwareInterface>
            <mechanicalReduction>1</mechanicalReduction>
        </actuator>
    </transmission>
    <transmission name="Rev28_tran">
        <type>transmission_interface/SimpleTransmission</type>
        <joint name="Rev28">
            <hardwareInterface>hardware_interface/EffortJointInterface</hardwareInterface>
        </joint>
        <actuator name="Rev28_actr">
            <hardwareInterface>hardware_interface/EffortJointInterface</hardwareInterface>
            <mechanicalReduction>1</mechanicalReduction>
        </actuator>
    </transmission>
    <gazebo reference="base_link">
        <material>Gazebo/Silver</material>
    </gazebo>
    <gazebo reference="joint_3">
        <material>Gazebo/Black</material>
    </gazebo>
    <gazebo reference="link1_1">
        <material>Gazebo/Silver</material>
    </gazebo>
    <gazebo reference="joint_6">
        <material>Gazebo/Black</material>
    </gazebo>
    <gazebo reference="link2_1">
        <material>Gazebo/Silver</material>
    </gazebo>
    <gazebo reference="joint_7">
        <material>Gazebo/Black</material>
    </gazebo>
    <gazebo reference="link3_1">
        <material>Gazebo/Silver</material>
    </gazebo>
    <gazebo reference="joint_8">
        <material>Gazebo/Black</material>
    </gazebo>
    <gazebo reference="link4_1">
        <material>Gazebo/Silver</material>
    </gazebo>
    <gazebo reference="base_link">
        <mu1>0.2</mu1>
        <mu2>0.2</mu2>
        <selfCollide>true</selfCollide>
        <gravity>true</gravity>
    </gazebo>
    <gazebo reference="joint_3">
        <mu1>0.2</mu1>
        <mu2>0.2</mu2>
        <selfCollide>true</selfCollide>
    </gazebo>
    <gazebo reference="link1_1">
        <mu1>0.2</mu1>
        <mu2>0.2</mu2>
        <selfCollide>true</selfCollide>
    </gazebo>
    <gazebo reference="joint_6">
        <mu1>0.2</mu1>
        <mu2>0.2</mu2>
        <selfCollide>true</selfCollide>
    </gazebo>
    <gazebo reference="link2_1">
        <mu1>0.2</mu1>
        <mu2>0.2</mu2>
        <selfCollide>true</selfCollide>
    </gazebo>
    <gazebo reference="joint_7">
        <mu1>0.2</mu1>
        <mu2>0.2</mu2>
        <selfCollide>true</selfCollide>
    </gazebo>
    <gazebo reference="link3_1">
        <mu1>0.2</mu1>
        <mu2>0.2</mu2>
        <selfCollide>true</selfCollide>
    </gazebo>
    <gazebo reference="joint_8">
        <mu1>0.2</mu1>
        <mu2>0.2</mu2>
        <selfCollide>true</selfCollide>
    </gazebo>
    <gazebo reference="link4_1">
        <mu1>0.2</mu1>
        <mu2>0.2</mu2>
        <selfCollide>true</selfCollide>
    </gazebo>
    <gazebo>
        <plugin filename="libgazebo_ros_control.so" name="control" />
    </gazebo>
    <transmission name="tran1">
        <type>transmission_interface/SimpleTransmission</type>
        <joint name="Rev22">
            <hardwareInterface>EffortJointInterface</hardwareInterface>
        </joint>
        <actuator name="motor1">
            <hardwareInterface>EffortJointInterface</hardwareInterface>
            <mechanicalReduction>1</mechanicalReduction>
        </actuator>
    </transmission>
    <link name="base_link">
        
<inertial>
            <origin rpy="0 0 0" xyz="-9.369973914028342e-06 0.001690566162448438 -0.008146420072387993" />
            <mass value="1.3507716732240094" />
            <inertia ixx="0.001302" ixy="0.0" ixz="-0.0" iyy="0.001034" iyz="4.9e-05" izz="0.000604" />
        </inertial>

        <visual>
            <origin rpy="0 0 0" xyz="0 0 0" />
            <geometry>
                <mesh filename="package://robotleg_description/meshes/base_link.stl" scale="0.001 0.001 0.001" />
            </geometry>
            <material name="silver" />
        </visual>
        <collision>
            <origin rpy="0 0 0" xyz="0 0 0" />
            <geometry>
                <mesh filename="package://robotleg_description/meshes/base_link.stl" scale="0.001 0.001 0.001" />
            </geometry>
        </collision>
    </link>
    <link name="joint_3">
        
<inertial>
            <origin rpy="0 0 0" xyz="1.441120806777516e-06 0.008079805361456853 0.00018129790863215256" />
            <mass value="0.0197994934350134" />
            <inertia ixx="1e-06" ixy="0.0" ixz="0.0" iyy="2e-06" iyz="0.0" izz="1e-06" />
        </inertial>

        <visual>
            <origin rpy="0 0 0" xyz="-0.0 0.042 0.023" />
            <geometry>
                <mesh filename="package://robotleg_description/meshes/joint_3.stl" scale="0.001 0.001 0.001" />
            </geometry>
            <material name="silver" />
        </visual>
        <collision>
            <origin rpy="0 0 0" xyz="-0.0 0.042 0.023" />
            <geometry>
                <mesh filename="package://robotleg_description/meshes/joint_3.stl" scale="0.001 0.001 0.001" />
            </geometry>
        </collision>
    </link>
    <link name="link1_1">
        
<inertial>
            <origin rpy="0 0 0" xyz="-0.005979810633911876 0.00048533672305276637 -0.057388402816478126" />
            <mass value="1.8576009926494503" />
            <inertia ixx="0.004643" ixy="-5.9e-05" ixz="-6.9e-05" iyy="0.002099" iyz="-0.001197" izz="0.003578" />
        </inertial>

        <visual>
            <origin rpy="0 0 0" xyz="-0.004763 0.0358 0.014751" />
            <geometry>
                <mesh filename="package://robotleg_description/meshes/link1_1.stl" scale="0.001 0.001 0.001" />
            </geometry>
            <material name="silver" />
        </visual>
        <collision>
            <origin rpy="0 0 0" xyz="-0.004763 0.0358 0.014751" />
            <geometry>
                <mesh filename="package://robotleg_description/meshes/link1_1.stl" scale="0.001 0.001 0.001" />
            </geometry>
        </collision>
    </link>
    <link name="joint_6">
        
<inertial>
            <origin rpy="0 0 0" xyz="-0.008079305361456908 1.4411208068276782e-06 0.00018094854372685543" />
            <mass value="0.0197994934350134" />
            <inertia ixx="2e-06" ixy="-0.0" ixz="-0.0" iyy="1e-06" iyz="0.0" izz="1e-06" />
        </inertial>

        <visual>
            <origin rpy="0 0 0" xyz="-0.042012 0.0608 0.095978" />
            <geometry>
                <mesh filename="package://robotleg_description/meshes/joint_6.stl" scale="0.001 0.001 0.001" />
            </geometry>
            <material name="silver" />
        </visual>
        <collision>
            <origin rpy="0 0 0" xyz="-0.042012 0.0608 0.095978" />
            <geometry>
                <mesh filename="package://robotleg_description/meshes/joint_6.stl" scale="0.001 0.001 0.001" />
            </geometry>
        </collision>
    </link>
    <link name="link2_1">
        
<inertial>
            <origin rpy="0 0 0" xyz="-0.03822567356962517 -0.004754559360021865 -0.15641251707812276" />
            <mass value="3.1185512630003815" />
            <inertia ixx="0.026318" ixy="-0.0" ixz="0.000423" iyy="0.027478" iyz="-8.6e-05" izz="0.001989" />
        </inertial>

        <visual>
            <origin rpy="0 0 0" xyz="-0.035812 0.056037 0.087729" />
            <geometry>
                <mesh filename="package://robotleg_description/meshes/link2_1.stl" scale="0.001 0.001 0.001" />
            </geometry>
            <material name="silver" />
        </visual>
        <collision>
            <origin rpy="0 0 0" xyz="-0.035812 0.056037 0.087729" />
            <geometry>
                <mesh filename="package://robotleg_description/meshes/link2_1.stl" scale="0.001 0.001 0.001" />
            </geometry>
        </collision>
    </link>
    <link name="joint_7">
        
<inertial>
            <origin rpy="0 0 0" xyz="-0.008079305361456839 9.411208068965671e-07 0.00018159917882104581" />
            <mass value="0.0197994934350134" />
            <inertia ixx="2e-06" ixy="-0.0" ixz="-0.0" iyy="1e-06" iyz="0.0" izz="1e-06" />
        </inertial>

        <visual>
            <origin rpy="0 0 0" xyz="-0.042012 0.060787 0.352157" />
            <geometry>
                <mesh filename="package://robotleg_description/meshes/joint_7.stl" scale="0.001 0.001 0.001" />
            </geometry>
            <material name="silver" />
        </visual>
        <collision>
            <origin rpy="0 0 0" xyz="-0.042012 0.060787 0.352157" />
            <geometry>
                <mesh filename="package://robotleg_description/meshes/joint_7.stl" scale="0.001 0.001 0.001" />
            </geometry>
        </collision>
    </link>
    <link name="link3_1">
        
<inertial>
            <origin rpy="0 0 0" xyz="-0.03822667342791625 -0.004754059283311046 -0.1564118661627638" />
            <mass value="3.118551263000379" />
            <inertia ixx="0.026318" ixy="-0.0" ixz="0.000423" iyy="0.027478" iyz="-8.6e-05" izz="0.001989" />
        </inertial>

        <visual>
            <origin rpy="0 0 0" xyz="-0.035813 0.056025 0.343908" />
            <geometry>
                <mesh filename="package://robotleg_description/meshes/link3_1.stl" scale="0.001 0.001 0.001" />
            </geometry>
            <material name="silver" />
        </visual>
        <collision>
            <origin rpy="0 0 0" xyz="-0.035813 0.056025 0.343908" />
            <geometry>
                <mesh filename="package://robotleg_description/meshes/link3_1.stl" scale="0.001 0.001 0.001" />
            </geometry>
        </collision>
    </link>
    <link name="joint_8">
        
<inertial>
            <origin rpy="0 0 0" xyz="-0.008080305361456805 1.4411208069525783e-06 0.00018124981391520745" />
            <mass value="0.0197994934350134" />
            <inertia ixx="2e-06" ixy="-0.0" ixz="-0.0" iyy="1e-06" iyz="0.0" izz="1e-06" />
        </inertial>

        <visual>
            <origin rpy="0 0 0" xyz="-0.042013 0.060775 0.608335" />
            <geometry>
                <mesh filename="package://robotleg_description/meshes/joint_8.stl" scale="0.001 0.001 0.001" />
            </geometry>
            <material name="silver" />
        </visual>
        <collision>
            <origin rpy="0 0 0" xyz="-0.042013 0.060775 0.608335" />
            <geometry>
                <mesh filename="package://robotleg_description/meshes/joint_8.stl" scale="0.001 0.001 0.001" />
            </geometry>
        </collision>
    </link>
    <link name="link4_1">
        
<inertial>
            <origin rpy="0 0 0" xyz="-0.0381264425947731 0.0047494988865498106 -0.11536857987982319" />
            <mass value="2.270179589776367" />
            <inertia ixx="0.011994" ixy="0.0" ixz="0.000468" iyy="0.012888" iyz="-8.5e-05" izz="0.001521" />
        </inertial>

        <visual>
            <origin rpy="0 0 0" xyz="-0.035812 0.065537 0.600086" />
            <geometry>
                <mesh filename="package://robotleg_description/meshes/link4_1.stl" scale="0.001 0.001 0.001" />
            </geometry>
            <material name="silver" />
        </visual>
        <collision>
            <origin rpy="0 0 0" xyz="-0.035812 0.065537 0.600086" />
            <geometry>
                <mesh filename="package://robotleg_description/meshes/link4_1.stl" scale="0.001 0.001 0.001" />
            </geometry>
        </collision>
    </link>
    <joint name="Rev22" type="continuous">
        <origin rpy="0 0 0" xyz="0.0 -0.042 -0.023" />
        <parent link="base_link" />
        <child link="joint_3" />
        <axis xyz="-0.0 -1.0 -0.0" />
    </joint>
    <joint name="Rigid23" type="fixed">
        <origin rpy="0 0 0" xyz="0.004763 0.0062 0.008249" />
        <parent link="joint_3" />
        <child link="link1_1" />
    </joint>
    <joint name="Rev24" type="continuous">
        <origin rpy="0 0 0" xyz="0.037249 -0.025 -0.081227" />
        <parent link="link1_1" />
        <child link="joint_6" />
        <axis xyz="1.0 -0.0 0.0" />
    </joint>
    <joint name="Rigid25" type="fixed">
        <origin rpy="0 0 0" xyz="-0.0062 0.004763 0.008249" />
        <parent link="joint_6" />
        <child link="link2_1" />
    </joint>
    <joint name="Rev26" type="continuous">
        <origin rpy="0 0 0" xyz="0.0062 -0.00475 -0.264428" />
        <parent link="link2_1" />
        <child link="joint_7" />
        <axis xyz="1.0 -0.0 0.0" />
    </joint>
    <joint name="Rigid27" type="fixed">
        <origin rpy="0 0 0" xyz="-0.006199 0.004762 0.008249" />
        <parent link="joint_7" />
        <child link="link3_1" />
    </joint>
    <joint name="Rev28" type="continuous">
        <origin rpy="0 0 0" xyz="0.0062 -0.00475 -0.264427" />
        <parent link="link3_1" />
        <child link="joint_8" />
        <axis xyz="1.0 -0.0 -0.0" />
    </joint>
    <joint name="Rigid29" type="fixed">
        <origin rpy="0 0 0" xyz="-0.006201 -0.004762 0.008249" />
        <parent link="joint_8" />
        <child link="link4_1" />
    </joint>
    <transmission name="trans_Rev22">
        <type>transmission_interface/SimpleTransmission</type>
        <joint name="Rev22">
            <hardwareInterface>hardware_interface/EffortJointInterface</hardwareInterface>
        </joint>
        <actuator name="Rev22_motor">
            <hardwareInterface>hardware_interface/EffortJointInterface</hardwareInterface>
            <mechanicalReduction>1</mechanicalReduction>
        </actuator>
    </transmission>
    <transmission name="trans_Rev24">
        <type>transmission_interface/SimpleTransmission</type>
        <joint name="Rev24">
            <hardwareInterface>hardware_interface/EffortJointInterface</hardwareInterface>
        </joint>
        <actuator name="Rev24_motor">
            <hardwareInterface>hardware_interface/EffortJointInterface</hardwareInterface>
            <mechanicalReduction>1</mechanicalReduction>
        </actuator>
    </transmission>
    <transmission name="trans_Rev26">
        <type>transmission_interface/SimpleTransmission</type>
        <joint name="Rev26">
            <hardwareInterface>hardware_interface/EffortJointInterface</hardwareInterface>
        </joint>
        <actuator name="Rev26_motor">
            <hardwareInterface>hardware_interface/EffortJointInterface</hardwareInterface>
            <mechanicalReduction>1</mechanicalReduction>
        </actuator>
    </transmission>
    <transmission name="trans_Rev28">
        <type>transmission_interface/SimpleTransmission</type>
        <joint name="Rev28">
            <hardwareInterface>hardware_interface/EffortJointInterface</hardwareInterface>
        </joint>
        <actuator name="Rev28_motor">
            <hardwareInterface>hardware_interface/EffortJointInterface</hardwareInterface>
            <mechanicalReduction>1</mechanicalReduction>
        </actuator>
    </transmission>
    <gazebo>
        <plugin name="gazebo_ros_control" filename="libgazebo_ros_control.so">
            <robotNamespace>/</robotNamespace>
        </plugin>
    </gazebo>
</robot>

<transmission name="Rev22_tran">
        <type>transmission_interface/SimpleTransmission</type>
        <joint name="Rev22">
            <hardwareInterface>hardware_interface/EffortJointInterface</hardwareInterface>
        </joint>
        <actuator name="Rev22_actr">
            <hardwareInterface>hardware_interface/EffortJointInterface</hardwareInterface>
            <mechanicalReduction>1</mechanicalReduction>
        </actuator>
    </transmission>
    <transmission name="Rev24_tran">
        <type>transmission_interface/SimpleTransmission</type>
        <joint name="Rev24">
            <hardwareInterface>hardware_interface/EffortJointInterface</hardwareInterface>
        </joint>
        <actuator name="Rev24_actr">
            <hardwareInterface>hardware_interface/EffortJointInterface</hardwareInterface>
            <mechanicalReduction>1</mechanicalReduction>
        </actuator>
    </transmission>
    <transmission name="Rev26_tran">
        <type>transmission_interface/SimpleTransmission</type>
        <joint name="Rev26">
            <hardwareInterface>hardware_interface/EffortJointInterface</hardwareInterface>
        </joint>
        <actuator name="Rev26_actr">
            <hardwareInterface>hardware_interface/EffortJointInterface</hardwareInterface>
            <mechanicalReduction>1</mechanicalReduction>
        </actuator>
    </transmission>
    <transmission name="Rev28_tran">
        <type>transmission_interface/SimpleTransmission</type>
        <joint name="Rev28">
            <hardwareInterface>hardware_interface/EffortJointInterface</hardwareInterface>
        </joint>
        <actuator name="Rev28_actr">
            <hardwareInterface>hardware_interface/EffortJointInterface</hardwareInterface>
            <mechanicalReduction>1</mechanicalReduction>
        </actuator>
    </transmission>
    <gazebo reference="base_link">
        <material>Gazebo/Silver</material>
    </gazebo>
    <gazebo reference="joint_3">
        <material>Gazebo/Black</material>
    </gazebo>
    <gazebo reference="link1_1">
        <material>Gazebo/Silver</material>
    </gazebo>
    <gazebo reference="joint_6">
        <material>Gazebo/Black</material>
    </gazebo>
    <gazebo reference="link2_1">
        <material>Gazebo/Silver</material>
    </gazebo>
    <gazebo reference="joint_7">
        <material>Gazebo/Black</material>
    </gazebo>
    <gazebo reference="link3_1">
        <material>Gazebo/Silver</material>
    </gazebo>
    <gazebo reference="joint_8">
        <material>Gazebo/Black</material>
    </gazebo>
    <gazebo reference="link4_1">
        <material>Gazebo/Silver</material>
    </gazebo>
    <gazebo reference="base_link">
        <mu1>0.2</mu1>
        <mu2>0.2</mu2>
        <selfCollide>true</selfCollide>
        <gravity>true</gravity>
    </gazebo>
    <gazebo reference="joint_3">
        <mu1>0.2</mu1>
        <mu2>0.2</mu2>
        <selfCollide>true</selfCollide>
    </gazebo>
    <gazebo reference="link1_1">
        <mu1>0.2</mu1>
        <mu2>0.2</mu2>
        <selfCollide>true</selfCollide>
    </gazebo>
    <gazebo reference="joint_6">
        <mu1>0.2</mu1>
        <mu2>0.2</mu2>
        <selfCollide>true</selfCollide>
    </gazebo>
    <gazebo reference="link2_1">
        <mu1>0.2</mu1>
        <mu2>0.2</mu2>
        <selfCollide>true</selfCollide>
    </gazebo>
    <gazebo reference="joint_7">
        <mu1>0.2</mu1>
        <mu2>0.2</mu2>
        <selfCollide>true</selfCollide>
    </gazebo>
    <gazebo reference="link3_1">
        <mu1>0.2</mu1>
        <mu2>0.2</mu2>
        <selfCollide>true</selfCollide>
    </gazebo>
    <gazebo reference="joint_8">
        <mu1>0.2</mu1>
        <mu2>0.2</mu2>
        <selfCollide>true</selfCollide>
    </gazebo>
    <gazebo reference="link4_1">
        <mu1>0.2</mu1>
        <mu2>0.2</mu2>
        <selfCollide>true</selfCollide>
    </gazebo>
    <gazebo>
        <plugin filename="libgazebo_ros_control.so" name="control" />
    </gazebo>
    <transmission name="tran1">
        <type>transmission_interface/SimpleTransmission</type>
        <joint name="Rev22">
            <hardwareInterface>EffortJointInterface</hardwareInterface>
        </joint>
        <actuator name="motor1">
            <hardwareInterface>EffortJointInterface</hardwareInterface>
            <mechanicalReduction>1</mechanicalReduction>
        </actuator>
    </transmission>
    <link name="base_link">
        <inertial>
            <origin rpy="0 0 0" xyz="-9.369973914028342e-06 0.001690566162448438 -0.008146420072387993" />
            <mass value="1.3507716732240094" />
            <inertia ixx="0.001302" ixy="0.0" ixz="-0.0" iyy="0.001034" iyz="4.9e-05" izz="0.000604" />
        </inertial>
        <visual>
            <origin rpy="0 0 0" xyz="0 0 0" />
            <geometry>
                <mesh filename="package://robotleg_description/meshes/base_link.stl" scale="0.001 0.001 0.001" />
            </geometry>
            <material name="silver" />
        </visual>
        <collision>
            <origin rpy="0 0 0" xyz="0 0 0" />
            <geometry>
                <mesh filename="package://robotleg_description/meshes/base_link.stl" scale="0.001 0.001 0.001" />
            </geometry>
        </collision>
    </link>
    <link name="joint_3">
        <inertial>
            <origin rpy="0 0 0" xyz="1.441120806777516e-06 0.008079805361456853 0.00018129790863215256" />
            <mass value="0.0197994934350134" />
            <inertia ixx="1e-06" ixy="0.0" ixz="0.0" iyy="2e-06" iyz="0.0" izz="1e-06" />
        </inertial>
        <visual>
            <origin rpy="0 0 0" xyz="-0.0 0.042 0.023" />
            <geometry>
                <mesh filename="package://robotleg_description/meshes/joint_3.stl" scale="0.001 0.001 0.001" />
            </geometry>
            <material name="silver" />
        </visual>
        <collision>
            <origin rpy="0 0 0" xyz="-0.0 0.042 0.023" />
            <geometry>
                <mesh filename="package://robotleg_description/meshes/joint_3.stl" scale="0.001 0.001 0.001" />
            </geometry>
        </collision>
    </link>
    <link name="link1_1">
        <inertial>
            <origin rpy="0 0 0" xyz="-0.005979810633911876 0.00048533672305276637 -0.057388402816478126" />
            <mass value="1.8576009926494503" />
            <inertia ixx="0.004643" ixy="-5.9e-05" ixz="-6.9e-05" iyy="0.002099" iyz="-0.001197" izz="0.003578" />
        </inertial>
        <visual>
            <origin rpy="0 0 0" xyz="-0.004763 0.0358 0.014751" />
            <geometry>
                <mesh filename="package://robotleg_description/meshes/link1_1.stl" scale="0.001 0.001 0.001" />
            </geometry>
            <material name="silver" />
        </visual>
        <collision>
            <origin rpy="0 0 0" xyz="-0.004763 0.0358 0.014751" />
            <geometry>
                <mesh filename="package://robotleg_description/meshes/link1_1.stl" scale="0.001 0.001 0.001" />
            </geometry>
        </collision>
    </link>
    <link name="joint_6">
        <inertial>
            <origin rpy="0 0 0" xyz="-0.008079305361456908 1.4411208068276782e-06 0.00018094854372685543" />
            <mass value="0.0197994934350134" />
            <inertia ixx="2e-06" ixy="-0.0" ixz="-0.0" iyy="1e-06" iyz="0.0" izz="1e-06" />
        </inertial>
        <visual>
            <origin rpy="0 0 0" xyz="-0.042012 0.0608 0.095978" />
            <geometry>
                <mesh filename="package://robotleg_description/meshes/joint_6.stl" scale="0.001 0.001 0.001" />
            </geometry>
            <material name="silver" />
        </visual>
        <collision>
            <origin rpy="0 0 0" xyz="-0.042012 0.0608 0.095978" />
            <geometry>
                <mesh filename="package://robotleg_description/meshes/joint_6.stl" scale="0.001 0.001 0.001" />
            </geometry>
        </collision>
    </link>
    <link name="link2_1">
        <inertial>
            <origin rpy="0 0 0" xyz="-0.03822567356962517 -0.004754559360021865 -0.15641251707812276" />
            <mass value="3.1185512630003815" />
            <inertia ixx="0.026318" ixy="-0.0" ixz="0.000423" iyy="0.027478" iyz="-8.6e-05" izz="0.001989" />
        </inertial>
        <visual>
            <origin rpy="0 0 0" xyz="-0.035812 0.056037 0.087729" />
            <geometry>
                <mesh filename="package://robotleg_description/meshes/link2_1.stl" scale="0.001 0.001 0.001" />
            </geometry>
            <material name="silver" />
        </visual>
        <collision>
            <origin rpy="0 0 0" xyz="-0.035812 0.056037 0.087729" />
            <geometry>
                <mesh filename="package://robotleg_description/meshes/link2_1.stl" scale="0.001 0.001 0.001" />
            </geometry>
        </collision>
    </link>
    <link name="joint_7">
        <inertial>
            <origin rpy="0 0 0" xyz="-0.008079305361456839 9.411208068965671e-07 0.00018159917882104581" />
            <mass value="0.0197994934350134" />
            <inertia ixx="2e-06" ixy="-0.0" ixz="-0.0" iyy="1e-06" iyz="0.0" izz="1e-06" />
        </inertial>
        <visual>
            <origin rpy="0 0 0" xyz="-0.042012 0.060787 0.352157" />
            <geometry>
                <mesh filename="package://robotleg_description/meshes/joint_7.stl" scale="0.001 0.001 0.001" />
            </geometry>
            <material name="silver" />
        </visual>
        <collision>
            <origin rpy="0 0 0" xyz="-0.042012 0.060787 0.352157" />
            <geometry>
                <mesh filename="package://robotleg_description/meshes/joint_7.stl" scale="0.001 0.001 0.001" />
            </geometry>
        </collision>
    </link>
    <link name="link3_1">
        <inertial>
            <origin rpy="0 0 0" xyz="-0.03822667342791625 -0.004754059283311046 -0.1564118661627638" />
            <mass value="3.118551263000379" />
            <inertia ixx="0.026318" ixy="-0.0" ixz="0.000423" iyy="0.027478" iyz="-8.6e-05" izz="0.001989" />
        </inertial>
        <visual>
            <origin rpy="0 0 0" xyz="-0.035813 0.056025 0.343908" />
            <geometry>
                <mesh filename="package://robotleg_description/meshes/link3_1.stl" scale="0.001 0.001 0.001" />
            </geometry>
            <material name="silver" />
        </visual>
        <collision>
            <origin rpy="0 0 0" xyz="-0.035813 0.056025 0.343908" />
            <geometry>
                <mesh filename="package://robotleg_description/meshes/link3_1.stl" scale="0.001 0.001 0.001" />
            </geometry>
        </collision>
    </link>
    <link name="joint_8">
        <inertial>
            <origin rpy="0 0 0" xyz="-0.008080305361456805 1.4411208069525783e-06 0.00018124981391520745" />
            <mass value="0.0197994934350134" />
            <inertia ixx="2e-06" ixy="-0.0" ixz="-0.0" iyy="1e-06" iyz="0.0" izz="1e-06" />
        </inertial>
        <visual>
            <origin rpy="0 0 0" xyz="-0.042013 0.060775 0.608335" />
            <geometry>
                <mesh filename="package://robotleg_description/meshes/joint_8.stl" scale="0.001 0.001 0.001" />
            </geometry>
            <material name="silver" />
        </visual>
        <collision>
            <origin rpy="0 0 0" xyz="-0.042013 0.060775 0.608335" />
            <geometry>
                <mesh filename="package://robotleg_description/meshes/joint_8.stl" scale="0.001 0.001 0.001" />
            </geometry>
        </collision>
    </link>
    <link name="link4_1">
        <inertial>
            <origin rpy="0 0 0" xyz="-0.0381264425947731 0.0047494988865498106 -0.11536857987982319" />
            <mass value="2.270179589776367" />
            <inertia ixx="0.011994" ixy="0.0" ixz="0.000468" iyy="0.012888" iyz="-8.5e-05" izz="0.001521" />
        </inertial>
        <visual>
            <origin rpy="0 0 0" xyz="-0.035812 0.065537 0.600086" />
            <geometry>
                <mesh filename="package://robotleg_description/meshes/link4_1.stl" scale="0.001 0.001 0.001" />
            </geometry>
            <material name="silver" />
        </visual>
        <collision>
            <origin rpy="0 0 0" xyz="-0.035812 0.065537 0.600086" />
            <geometry>
                <mesh filename="package://robotleg_description/meshes/link4_1.stl" scale="0.001 0.001 0.001" />
            </geometry>
        </collision>
    </link>
    <joint name="Rev22" type="continuous">
        <origin rpy="0 0 0" xyz="0.0 -0.042 -0.023" />
        <parent link="base_link" />
        <child link="joint_3" />
        <axis xyz="-0.0 -1.0 -0.0" />
    </joint>
    <joint name="Rigid23" type="fixed">
        <origin rpy="0 0 0" xyz="0.004763 0.0062 0.008249" />
        <parent link="joint_3" />
        <child link="link1_1" />
    </joint>
    <joint name="Rev24" type="continuous">
        <origin rpy="0 0 0" xyz="0.037249 -0.025 -0.081227" />
        <parent link="link1_1" />
        <child link="joint_6" />
        <axis xyz="1.0 -0.0 0.0" />
    </joint>
    <joint name="Rigid25" type="fixed">
        <origin rpy="0 0 0" xyz="-0.0062 0.004763 0.008249" />
        <parent link="joint_6" />
        <child link="link2_1" />
    </joint>
    <joint name="Rev26" type="continuous">
        <origin rpy="0 0 0" xyz="0.0062 -0.00475 -0.264428" />
        <parent link="link2_1" />
        <child link="joint_7" />
        <axis xyz="1.0 -0.0 0.0" />
    </joint>
    <joint name="Rigid27" type="fixed">
        <origin rpy="0 0 0" xyz="-0.006199 0.004762 0.008249" />
        <parent link="joint_7" />
        <child link="link3_1" />
    </joint>
    <joint name="Rev28" type="continuous">
        <origin rpy="0 0 0" xyz="0.0062 -0.00475 -0.264427" />
        <parent link="link3_1" />
        <child link="joint_8" />
        <axis xyz="1.0 -0.0 -0.0" />
    </joint>
    <joint name="Rigid29" type="fixed">
        <origin rpy="0 0 0" xyz="-0.006201 -0.004762 0.008249" />
        <parent link="joint_8" />
        <child link="link4_1" />
    </joint>
    <transmission name="trans_Rev22">
        <type>transmission_interface/SimpleTransmission</type>
        <joint name="Rev22">
            <hardwareInterface>hardware_interface/EffortJointInterface</hardwareInterface>
        </joint>
        <actuator name="Rev22_motor">
            <hardwareInterface>hardware_interface/EffortJointInterface</hardwareInterface>
            <mechanicalReduction>1</mechanicalReduction>
        </actuator>
    </transmission>
    <transmission name="trans_Rev24">
        <type>transmission_interface/SimpleTransmission</type>
        <joint name="Rev24">
            <hardwareInterface>hardware_interface/EffortJointInterface</hardwareInterface>
        </joint>
        <actuator name="Rev24_motor">
            <hardwareInterface>hardware_interface/EffortJointInterface</hardwareInterface>
            <mechanicalReduction>1</mechanicalReduction>
        </actuator>
    </transmission>
    <transmission name="trans_Rev26">
        <type>transmission_interface/SimpleTransmission</type>
        <joint name="Rev26">
            <hardwareInterface>hardware_interface/EffortJointInterface</hardwareInterface>
        </joint>
        <actuator name="Rev26_motor">
            <hardwareInterface>hardware_interface/EffortJointInterface</hardwareInterface>
            <mechanicalReduction>1</mechanicalReduction>
        </actuator>
    </transmission>
    <transmission name="trans_Rev28">
        <type>transmission_interface/SimpleTransmission</type>
        <joint name="Rev28">
            <hardwareInterface>hardware_interface/EffortJointInterface</hardwareInterface>
        </joint>
        <actuator name="Rev28_motor">
            <hardwareInterface>hardware_interface/EffortJointInterface</hardwareInterface>
            <mechanicalReduction>1</mechanicalReduction>
        </actuator>
    </transmission>
    <gazebo>
        <plugin name="gazebo_ros_control" filename="libgazebo_ros_control.so">
            <robotNamespace>/</robotNamespace>
        </plugin>
    </gazebo>
</robot>